Workbook
Name KPIรายวัน: '[1]Electric Cost'!#REF!
Name ก.พ.: '[1]Electric Cost'!#REF!
Name ตัวแบ่งส่วนข้อมูล_วันที่: #N/A
Name ไทม์ไลน์ดั้งเดิม_วันที่: #N/A
Name มี.ค: '[1]Electric Cost'!#REF!

Sheet Pivote
A3: ป้ายชื่อแถว | B3: Soft Mark Up | C3: มิเตอร์น้ำ Boiler | D3: น้ำ CONDENSATE กลับ | E3: ป้ายชื่อแถว | F3: Target | G3: % condensate | H3: ป้ายชื่อแถว | I3: CON Return bhs | J3: CON Return yueli | K3: ป้ายชื่อแถว | L3: รวมยอดใช้สตีม | M3: ป้ายชื่อแถว | N3: ค่าเฉลี่ย ของ %DIFF | P3: %DIFF | Q3: =GETPIVOTDATA("%DIFF",$N$3) -> -0.046189991
A4: 45992 | B4: 15 | C4: 91 | D4: 76 | E4: 45992 | F4: 0.8 | G4: 0.86757991 | H4: 45992 | I4: 34.074725 | J4: 39.085714 | K4: 45992 | L4: 87.6 | M4: 45992 | N4: 0.084474886 | P4: Target | Q4: =GETPIVOTDATA("Target",$F$3) -> 0.8
A5: 45993 | B5: 20 | C5: 60 | D5: 40 | E5: 45993 | F5: 0.8 | G5: 0.37348273 | H5: 45993 | I5: 28.333333 | J5: 43.066667 | K5: 45993 | L5: 107.1 | M5: 45993 | N5: -0.53314659 | P5: % condensate | Q5: =GETPIVOTDATA(" % condensate ",$E$3) -> 0.76304801
A6: 45994 | B6: 20 | C6: 68 | D6: 48 | E6: 45994 | F6: 0.8 | G6: 0.44568245 | H6: 45994 | I6: 30.352941 | J6: 45.670588 | K6: 45994 | L6: 107.7 | M6: 45994 | N6: -0.44289694
A7: 45995 | B7: 20 | C7: 97 | D7: 77 | E7: 45995 | F7: 0.8 | G7: 0.724365 | H7: 45995 | I7: 35.086598 | J7: 49.295876 | K7: 45995 | L7: 106.3 | M7: 45995 | N7: -0.094543744
A8: 45996 | B8: 19 | C8: 84 | D8: 65 | E8: 45996 | F8: 0.8 | G8: 0.60018467 | H8: 45996 | I8: 33.27381 | J8: 50.529762 | K8: 45996 | L8: 108.3 | M8: 45996 | N8: -0.24976916
A9: 45997 | B9: 18 | C9: 85 | D9: 67 | E9: 45997 | F9: 0.8 | G9: 0.61637534 | H9: 45997 | I9: 33.421176 | J9: 52.26 | K9: 45997 | L9: 108.7 | M9: 45997 | N9: -0.22953082
A10: 45998 | B10: 9 | C10: 88 | D10: 79 | E10: 45998 | F10: 0.8 | G10: 1.7136659 | H10: 45998 | I10: 20.109091 | J10: 21.276136 | K10: 45998 | L10: 46.1 | M10: 45998 | N10: 1.1420824
A11: ผลรวมทั้งหมด | B11: 121 | C11: 573 | D11: 452 | E11: ผลรวมทั้งหมด | F11: 0.8 | G11: 0.76304801 | H11: ผลรวมทั้งหมด | I11: 214.65167 | J11: 301.18474 | K11: ผลรวมทั้งหมด | L11: 671.8 | M11: ผลรวมทั้งหมด | N11: -0.046189991

Sheet Ghap

Sheet %condent
A1: วันที่ | B1: Soft Mark Up | C1: มิเตอร์น้ำ Boiler | D1: น้ำ CONDENSATE กลับ | E1: Target | F1: % condensate | G1: %DIFF | H1: CON Return bhs | I1: condensate bhs% | J1: CON Return yueli | K1: condensate yueli% | L1: ยอดการใช้ Steam BHS | M1: ยอดการใช้ Steam YUELI | N1: ยอดการใช้ Steam BHS% | O1: ยอดการใช้ Steam YUELI% | P1: รวมยอดใช้สตีม
A2: ='[2]1.บาทต่อการผลิต'!A4 -> 45901 | B2: =VLOOKUP(Condensate[[#This Row],[วันที่]],'[3]TABLE DATA'!$V:$W,2,0) -> 10 | C2: =[2]มิเตอร์น้ำ!AT3 -> 64 | D2: =Condensate[[#This Row],[มิเตอร์น้ำ Boiler]]-Condensate[[#This Row],[Soft Mark Up]] -> 54 | E2: 0.8 | F2: =IFERROR(Condensate[[#This Row],[น้ำ CONDENSATE กลับ]]/Condensate[[#This Row],[รวมยอดใช้สตีม]],0) -> 0.71713147 | G2: =(Condensate[[#This Row],[% condensate ]]-Condensate[[#This Row],[Target]])/80*100 -> -0.10358566 | H2: =IFERROR(Condensate[[#This Row],[ยอดการใช้ Steam BHS]]*Condensate[[#This Row],[น้ำ CONDENSATE กลับ]]/Condensate[[#This Row],[มิเตอร์น้ำ Boiler]],0) -> 40.5 | I2: =IFERROR(Condensate[[#This Row],[CON Return bhs]]/Condensate[[#This Row],[ยอดการใช้ Steam BHS]],0) -> 0.84375 | J2: =IFERROR(Condensate[[#This Row],[ยอดการใช้ Steam YUELI]]*Condensate[[#This Row],[น้ำ CONDENSATE กลับ]]/Condensate[[#This Row],[มิเตอร์น้ำ Boiler]],0) -> 23.034375 | K2: =IFERROR(Condensate[[#This Row],[CON Return yueli]]/Condensate[[#This Row],[ยอดการใช้ Steam YUELI]],0) -> 0.84375 | L2: ='[2]ข้อมูลตัด ถ่านหิน'!C6 -> 48 | M2: ='[2]ข้อมูลตัด ถ่านหิน'!D6 -> 27.3 | N2: =IFERROR(Condensate[[#This Row],[ยอดการใช้ Steam BHS]]*100/Condensate[[#This Row],[รวมยอดใช้สตีม]]/100,0) -> 0.6374502 | O2: =IFERROR(Condensate[[#This Row],[ยอดการใช้ Steam YUELI]]*100/Condensate[[#This Row],[รวมยอดใช้สตีม]]/100,0) -> 0.3625498 | P2: =SUM(Condensate[[#This Row],[ยอดการใช้ Steam BHS]:[ยอดการใช้ Steam YUELI]]) -> 75.3
A3: ='[2]1.บาทต่อการผลิต'!A5 -> 45902 | B3: =VLOOKUP(Condensate[[#This Row],[วันที่]],'[3]TABLE DATA'!$V:$W,2,0) -> 21 | C3: =[2]มิเตอร์น้ำ!AT4 -> 91 | D3: =Condensate[[#This Row],[มิเตอร์น้ำ Boiler]]-Condensate[[#This Row],[Soft Mark Up]] -> 70 | E3: =E2 -> 0.8 | F3: =IFERROR(Condensate[[#This Row],[น้ำ CONDENSATE กลับ]]/Condensate[[#This Row],[รวมยอดใช้สตีม]],0) -> 0.89058524 | G3: =(Condensate[[#This Row],[% condensate ]]-Condensate[[#This Row],[Target]])/80*100 -> 0.11323155 | H3: =IFERROR(Condensate[[#This Row],[ยอดการใช้ Steam BHS]]*Condensate[[#This Row],[น้ำ CONDENSATE กลับ]]/Condensate[[#This Row],[มิเตอร์น้ำ Boiler]],0) -> 32.153846 | I3: =IFERROR(Condensate[[#This Row],[CON Return bhs]]/Condensate[[#This Row],[ยอดการใช้ Steam BHS]],0) -> 0.76923077 | J3: =IFERROR(Condensate[[#This Row],[ยอดการใช้ Steam YUELI]]*Condensate[[#This Row],[น้ำ CONDENSATE กลับ]]/Condensate[[#This Row],[มิเตอร์น้ำ Boiler]],0) -> 28.307692 | K3: =IFERROR(Condensate[[#This Row],[CON Return yueli]]/Condensate[[#This Row],[ยอดการใช้ Steam YUELI]],0) -> 0.76923077 | L3: ='[2]ข้อมูลตัด ถ่านหิน'!C7 -> 41.8 | M3: ='[2]ข้อมูลตัด ถ่านหิน'!D7 -> 36.8 | N3: =IFERROR(Condensate[[#This Row],[ยอดการใช้ Steam BHS]]*100/Condensate[[#This Row],[รวมยอดใช้สตีม]]/100,0) -> 0.53180662 | O3: =IFERROR(Condensate[[#This Row],[ยอดการใช้ Steam YUELI]]*100/Condensate[[#This Row],[รวมยอดใช้สตีม]]/100,0) -> 0.46819338 | P3: =SUM(Condensate[[#This Row],[ยอดการใช้ Steam BHS]:[ยอดการใช้ Steam YUELI]]) -> 78.6
A4: ='[2]1.บาทต่อการผลิต'!A6 -> 45903 | B4: =VLOOKUP(Condensate[[#This Row],[วันที่]],'[3]TABLE DATA'!$V:$W,2,0) -> 22 | C4: =[2]มิเตอร์น้ำ!AT5 -> 87 | D4: =Condensate[[#This Row],[มิเตอร์น้ำ Boiler]]-Condensate[[#This Row],[Soft Mark Up]] -> 65 | E4: =E3 -> 0.8 | F4: =IFERROR(Condensate[[#This Row],[น้ำ CONDENSATE กลับ]]/Condensate[[#This Row],[รวมยอดใช้สตีม]],0) -> 0.82070707 | G4: =(Condensate[[#This Row],[% condensate ]]-Condensate[[#This Row],[Target]])/80*100 -> 0.025883838 | H4: =IFERROR(Condensate[[#This Row],[ยอดการใช้ Steam BHS]]*Condensate[[#This Row],[น้ำ CONDENSATE กลับ]]/Condensate[[#This Row],[มิเตอร์น้ำ Boiler]],0) -> 30.258621 | I4: =IFERROR(Condensate[[#This Row],[CON Return bhs]]/Condensate[[#This Row],[ยอดการใช้ Steam BHS]],0) -> 0.74712644 | J4: =IFERROR(Condensate[[#This Row],[ยอดการใช้ Steam YUELI]]*Condensate[[#This Row],[น้ำ CONDENSATE กลับ]]/Condensate[[#This Row],[มิเตอร์น้ำ Boiler]],0) -> 28.913793 | K4: =IFERROR(Condensate[[#This Row],[CON Return yueli]]/Condensate[[#This Row],[ยอดการใช้ Steam YUELI]],0) -> 0.74712644 | L4: ='[2]ข้อมูลตัด ถ่านหิน'!C8 -> 40.5 | M4: ='[2]ข้อมูลตัด ถ่านหิน'!D8 -> 38.7 | N4: =IFERROR(Condensate[[#This Row],[ยอดการใช้ Steam BHS]]*100/Condensate[[#This Row],[รวมยอดใช้สตีม]]/100,0) -> 0.51136364 | O4: =IFERROR(Condensate[[#This Row],[ยอดการใช้ Steam YUELI]]*100/Condensate[[#This Row],[รวมยอดใช้สตีม]]/100,0) -> 0.48863636 | P4: =SUM(Condensate[[#This Row],[ยอดการใช้ Steam BHS]:[ยอดการใช้ Steam YUELI]]) -> 79.2
A5: ='[2]1.บาทต่อการผลิต'!A7 -> 45904 | B5: =VLOOKUP(Condensate[[#This Row],[วันที่]],'[3]TABLE DATA'!$V:$W,2,0) -> 19 | C5: =[2]มิเตอร์น้ำ!AT6 -> 101 | D5: =Condensate[[#This Row],[มิเตอร์น้ำ Boiler]]-Condensate[[#This Row],[Soft Mark Up]] -> 82 | E5: =E4 -> 0.8 | F5: =IFERROR(Condensate[[#This Row],[น้ำ CONDENSATE กลับ]]/Condensate[[#This Row],[รวมยอดใช้สตีม]],0) -> 0.81836327 | G5: =(Condensate[[#This Row],[% condensate ]]-Condensate[[#This Row],[Target]])/80*100 -> 0.022954092 | H5: =IFERROR(Condensate[[#This Row],[ยอดการใช้ Steam BHS]]*Condensate[[#This Row],[น้ำ CONDENSATE กลับ]]/Condensate[[#This Row],[มิเตอร์น้ำ Boiler]],0) -> 32.8 | I5: =IFERROR(Condensate[[#This Row],[CON Return bhs]]/Condensate[[#This Row],[ยอดการใช้ Steam BHS]],0) -> 0.81188119 | J5: =IFERROR(Condensate[[#This Row],[ยอดการใช้ Steam YUELI]]*Condensate[[#This Row],[น้ำ CONDENSATE กลับ]]/Condensate[[#This Row],[มิเตอร์น้ำ Boiler]],0) -> 48.550495 | K5: =IFERROR(Condensate[[#This Row],[CON Return yueli]]/Condensate[[#This Row],[ยอดการใช้ Steam YUELI]],0) -> 0.81188119 | L5: ='[2]ข้อมูลตัด ถ่านหิน'!C9 -> 40.4 | M5: ='[2]ข้อมูลตัด ถ่านหิน'!D9 -> 59.8 | N5: =IFERROR(Condensate[[#This Row],[ยอดการใช้ Steam BHS]]*100/Condensate[[#This Row],[รวมยอดใช้สตีม]]/100,0) -> 0.40319361 | O5: =IFERROR(Condensate[[#This Row],[ยอดการใช้ Steam YUELI]]*100/Condensate[[#This Row],[รวมยอดใช้สตีม]]/100,0) -> 0.59680639 | P5: =SUM(Condensate[[#This Row],[ยอดการใช้ Steam BHS]:[ยอดการใช้ Steam YUELI]]) -> 100.2
A6: ='[2]1.บาทต่อการผลิต'!A8 -> 45905 | B6: =VLOOKUP(Condensate[[#This Row],[วันที่]],'[3]TABLE DATA'!$V:$W,2,0) -> 21 | C6: =[2]มิเตอร์น้ำ!AT7 -> 86 | D6: =Condensate[[#This Row],[มิเตอร์น้ำ Boiler]]-Condensate[[#This Row],[Soft Mark Up]] -> 65 | E6: =E5 -> 0.8 | F6: =IFERROR(Condensate[[#This Row],[น้ำ CONDENSATE กลับ]]/Condensate[[#This Row],[รวมยอดใช้สตีม]],0) -> 0.83226633 | G6: =(Condensate[[#This Row],[% condensate ]]-Condensate[[#This Row],[Target]])/80*100 -> 0.040332907 | H6: =IFERROR(Condensate[[#This Row],[ยอดการใช้ Steam BHS]]*Condensate[[#This Row],[น้ำ CONDENSATE กลับ]]/Condensate[[#This Row],[มิเตอร์น้ำ Boiler]],0) -> 30.686047 | I6: =IFERROR(Condensate[[#This Row],[CON Return bhs]]/Condensate[[#This Row],[ยอดการใช้ Steam BHS]],0) -> 0.75581395 | J6: =IFERROR(Condensate[[#This Row],[ยอดการใช้ Steam YUELI]]*Condensate[[#This Row],[น้ำ CONDENSATE กลับ]]/Condensate[[#This Row],[มิเตอร์น้ำ Boiler]],0) -> 28.343023 | K6: =IFERROR(Condensate[[#This Row],[CON Return yueli]]/Condensate[[#This Row],[ยอดการใช้ Steam YUELI]],0) -> 0.75581395 | L6: ='[2]ข้อมูลตัด ถ่านหิน'!C10 -> 40.6 | M6: ='[2]ข้อมูลตัด ถ่านหิน'!D10 -> 37.5 | N6: =IFERROR(Condensate[[#This Row],[ยอดการใช้ Steam BHS]]*100/Condensate[[#This Row],[รวมยอดใช้สตีม]]/100,0) -> 0.51984635 | O6: =IFERROR(Condensate[[#This Row],[ยอดการใช้ Steam YUELI]]*100/Condensate[[#This Row],[รวมยอดใช้สตีม]]/100,0) -> 0.48015365 | P6: =SUM(Condensate[[#This Row],[ยอดการใช้ Steam BHS]:[ยอดการใช้ Steam YUELI]]) -> 78.1
A7: ='[2]1.บาทต่อการผลิต'!A9 -> 45906 | B7: =VLOOKUP(Condensate[[#This Row],[วันที่]],'[3]TABLE DATA'!$V:$W,2,0) -> 20 | C7: =[2]มิเตอร์น้ำ!AT8 -> 106 | D7: =Condensate[[#This Row],[มิเตอร์น้ำ Boiler]]-Condensate[[#This Row],[Soft Mark Up]] -> 86 | E7: =E6 -> 0.8 | F7: =IFERROR(Condensate[[#This Row],[น้ำ CONDENSATE กลับ]]/Condensate[[#This Row],[รวมยอดใช้สตีม]],0) -> 0.81362346 | G7: =(Condensate[[#This Row],[% condensate ]]-Condensate[[#This Row],[Target]])/80*100 -> 0.017029328 | H7: =IFERROR(Condensate[[#This Row],[ยอดการใช้ Steam BHS]]*Condensate[[#This Row],[น้ำ CONDENSATE กลับ]]/Condensate[[#This Row],[มิเตอร์น้ำ Boiler]],0) -> 32.209434 | I7: =IFERROR(Condensate[[#This Row],[CON Return bhs]]/Condensate[[#This Row],[ยอดการใช้ Steam BHS]],0) -> 0.81132075 | J7: =IFERROR(Condensate[[#This Row],[ยอดการใช้ Steam YUELI]]*Condensate[[#This Row],[น้ำ CONDENSATE กลับ]]/Condensate[[#This Row],[มิเตอร์น้ำ Boiler]],0) -> 53.54717 | K7: =IFERROR(Condensate[[#This Row],[CON Return yueli]]/Condensate[[#This Row],[ยอดการใช้ Steam YUELI]],0) -> 0.81132075 | L7: ='[2]ข้อมูลตัด ถ่านหิน'!C11 -> 39.7 | M7: ='[2]ข้อมูลตัด ถ่านหิน'!D11 -> 66 | N7: =IFERROR(Condensate[[#This Row],[ยอดการใช้ Steam BHS]]*100/Condensate[[#This Row],[รวมยอดใช้สตีม]]/100,0) -> 0.3755913 | O7: =IFERROR(Condensate[[#This Row],[ยอดการใช้ Steam YUELI]]*100/Condensate[[#This Row],[รวมยอดใช้สตีม]]/100,0) -> 0.6244087 | P7: =SUM(Condensate[[#This Row],[ยอดการใช้ Steam BHS]:[ยอดการใช้ Steam YUELI]]) -> 105.7
A8: ='[2]1.บาทต่อการผลิต'!A10 -> 45907 | B8: =VLOOKUP(Condensate[[#This Row],[วันที่]],'[3]TABLE DATA'!$V:$W,2,0) -> 15 | C8: =[2]มิเตอร์น้ำ!AT9 -> 36 | D8: =Condensate[[#This Row],[มิเตอร์น้ำ Boiler]]-Condensate[[#This Row],[Soft Mark Up]] -> 21 | E8: =E7 -> 0.8 | F8: =IFERROR(Condensate[[#This Row],[น้ำ CONDENSATE กลับ]]/Condensate[[#This Row],[รวมยอดใช้สตีม]],0) -> 0.64220183 | G8: =(Condensate[[#This Row],[% condensate ]]-Condensate[[#This Row],[Target]])/80*100 -> -0.19724771 | H8: =IFERROR(Condensate[[#This Row],[ยอดการใช้ Steam BHS]]*Condensate[[#This Row],[น้ำ CONDENSATE กลับ]]/Condensate[[#This Row],[มิเตอร์น้ำ Boiler]],0) -> 11.316667 | I8: =IFERROR(Condensate[[#This Row],[CON Return bhs]]/Condensate[[#This Row],[ยอดการใช้ Steam BHS]],0) -> 0.58333333 | J8: =IFERROR(Condensate[[#This Row],[ยอดการใช้ Steam YUELI]]*Condensate[[#This Row],[น้ำ CONDENSATE กลับ]]/Condensate[[#This Row],[มิเตอร์น้ำ Boiler]],0) -> 7.7583333 | K8: =IFERROR(Condensate[[#This Row],[CON Return yueli]]/Condensate[[#This Row],[ยอดการใช้ Steam YUELI]],0) -> 0.58333333 | L8: ='[2]ข้อมูลตัด ถ่านหิน'!C12 -> 19.4 | M8: ='[2]ข้อมูลตัด ถ่านหิน'!D12 -> 13.3 | N8: =IFERROR(Condensate[[#This Row],[ยอดการใช้ Steam BHS]]*100/Condensate[[#This Row],[รวมยอดใช้สตีม]]/100,0) -> 0.59327217 | O8: =IFERROR(Condensate[[#This Row],[ยอดการใช้ Steam YUELI]]*100/Condensate[[#This Row],[รวมยอดใช้สตีม]]/100,0) -> 0.40672783 | P8: =SUM(Condensate[[#This Row],[ยอดการใช้ Steam BHS]:[ยอดการใช้ Steam YUELI]]) -> 32.7
A9: ='[2]1.บาทต่อการผลิต'!A11 -> 45908 | B9: =VLOOKUP(Condensate[[#This Row],[วันที่]],'[3]TABLE DATA'!$V:$W,2,0) -> 8 | C9: =[2]มิเตอร์น้ำ!AT10 -> 82 | D9: =Condensate[[#This Row],[มิเตอร์น้ำ Boiler]]-Condensate[[#This Row],[Soft Mark Up]] -> 74 | E9: =E8 -> 0.8 | F9: =IFERROR(Condensate[[#This Row],[น้ำ CONDENSATE กลับ]]/Condensate[[#This Row],[รวมยอดใช้สตีม]],0) -> 1.0393258 | G9: =(Condensate[[#This Row],[% condensate ]]-Condensate[[#This Row],[Target]])/80*100 -> 0.2991573 | H9: =IFERROR(Condensate[[#This Row],[ยอดการใช้ Steam BHS]]*Condensate[[#This Row],[น้ำ CONDENSATE กลับ]]/Condensate[[#This Row],[มิเตอร์น้ำ Boiler]],0) -> 27.614634 | I9: =IFERROR(Condensate[[#This Row],[CON Return bhs]]/Condensate[[#This Row],[ยอดการใช้ Steam BHS]],0) -> 0.90243902 | J9: =IFERROR(Condensate[[#This Row],[ยอดการใช้ Steam YUELI]]*Condensate[[#This Row],[น้ำ CONDENSATE กลับ]]/Condensate[[#This Row],[มิเตอร์น้ำ Boiler]],0) -> 36.639024 | K9: =IFERROR(Condensate[[#This Row],[CON Return yueli]]/Condensate[[#This Row],[ยอดการใช้ Steam YUELI]],0) -> 0.90243902 | L9: ='[2]ข้อมูลตัด ถ่านหิน'!C13 -> 30.6 | M9: ='[2]ข้อมูลตัด ถ่านหิน'!D13 -> 40.6 | N9: =IFERROR(Condensate[[#This Row],[ยอดการใช้ Steam BHS]]*100/Condensate[[#This Row],[รวมยอดใช้สตีม]]/100,0) -> 0.42977528 | O9: =IFERROR(Condensate[[#This Row],[ยอดการใช้ Steam YUELI]]*100/Condensate[[#This Row],[รวมยอดใช้สตีม]]/100,0) -> 0.57022472 | P9: =SUM(Condensate[[#This Row],[ยอดการใช้ Steam BHS]:[ยอดการใช้ Steam YUELI]]) -> 71.2
A10: ='[2]1.บาทต่อการผลิต'!A12 -> 45909 | B10: =VLOOKUP(Condensate[[#This Row],[วันที่]],'[3]TABLE DATA'!$V:$W,2,0) -> 21 | C10: =[2]มิเตอร์น้ำ!AT11 -> 90 | D10: =Condensate[[#This Row],[มิเตอร์น้ำ Boiler]]-Condensate[[#This Row],[Soft Mark Up]] -> 69 | E10: =E9 -> 0.8 | F10: =IFERROR(Condensate[[#This Row],[น้ำ CONDENSATE กลับ]]/Condensate[[#This Row],[รวมยอดใช้สตีม]],0) -> 0.85501859 | G10: =(Condensate[[#This Row],[% condensate ]]-Condensate[[#This Row],[Target]])/80*100 -> 0.068773234 | H10: =IFERROR(Condensate[[#This Row],[ยอดการใช้ Steam BHS]]*Condensate[[#This Row],[น้ำ CONDENSATE กลับ]]/Condensate[[#This Row],[มิเตอร์น้ำ Boiler]],0) -> 31.05 | I10: =IFERROR(Condensate[[#This Row],[CON Return bhs]]/Condensate[[#This Row],[ยอดการใช้ Steam BHS]],0) -> 0.76666667 | J10: =IFERROR(Condensate[[#This Row],[ยอดการใช้ Steam YUELI]]*Condensate[[#This Row],[น้ำ CONDENSATE กลับ]]/Condensate[[#This Row],[มิเตอร์น้ำ Boiler]],0) -> 30.82 | K10: =IFERROR(Condensate[[#This Row],[CON Return yueli]]/Condensate[[#This Row],[ยอดการใช้ Steam YUELI]],0) -> 0.76666667 | L10: ='[2]ข้อมูลตัด ถ่านหิน'!C14 -> 40.5 | M10: ='[2]ข้อมูลตัด ถ่านหิน'!D14 -> 40.2 | N10: =IFERROR(Condensate[[#This Row],[ยอดการใช้ Steam BHS]]*100/Condensate[[#This Row],[รวมยอดใช้สตีม]]/100,0) -> 0.50185874 | O10: =IFERROR(Condensate[[#This Row],[ยอดการใช้ Steam YUELI]]*100/Condensate[[#This Row],[รวมยอดใช้สตีม]]/100,0) -> 0.49814126 | P10: =SUM(Condensate[[#This Row],[ยอดการใช้ Steam BHS]:[ยอดการใช้ Steam YUELI]]) -> 80.7
A11: ='[2]1.บาทต่อการผลิต'!A13 -> 45910 | B11: =VLOOKUP(Condensate[[#This Row],[วันที่]],'[3]TABLE DATA'!$V:$W,2,0) -> 19 | C11: =[2]มิเตอร์น้ำ!AT12 -> 89 | D11: =Condensate[[#This Row],[มิเตอร์น้ำ Boiler]]-Condensate[[#This Row],[Soft Mark Up]] -> 70 | E11: =E10 -> 0.8 | F11: =IFERROR(Condensate[[#This Row],[น้ำ CONDENSATE กลับ]]/Condensate[[#This Row],[รวมยอดใช้สตีม]],0) -> 0.85470085 | G11: =(Condensate[[#This Row],[% condensate ]]-Condensate[[#This Row],[Target]])/80*100 -> 0.068376068 | H11: =IFERROR(Condensate[[#This Row],[ยอดการใช้ Steam BHS]]*Condensate[[#This Row],[น้ำ CONDENSATE กลับ]]/Condensate[[#This Row],[มิเตอร์น้ำ Boiler]],0) -> 31.539326 | I11: =IFERROR(Condensate[[#This Row],[CON Return bhs]]/Condensate[[#This Row],[ยอดการใช้ Steam BHS]],0) -> 0.78651685 | J11: =IFERROR(Condensate[[#This Row],[ยอดการใช้ Steam YUELI]]*Condensate[[#This Row],[น้ำ CONDENSATE กลับ]]/Condensate[[#This Row],[มิเตอร์น้ำ Boiler]],0) -> 32.876404 | K11: =IFERROR(Condensate[[#This Row],[CON Return yueli]]/Condensate[[#This Row],[ยอดการใช้ Steam YUELI]],0) -> 0.78651685 | L11: ='[2]ข้อมูลตัด ถ่านหิน'!C15 -> 40.1 | M11: ='[2]ข้อมูลตัด ถ่านหิน'!D15 -> 41.8 | N11: =IFERROR(Condensate[[#This Row],[ยอดการใช้ Steam BHS]]*100/Condensate[[#This Row],[รวมยอดใช้สตีม]]/100,0) -> 0.48962149 | O11: =IFERROR(Condensate[[#This Row],[ยอดการใช้ Steam YUELI]]*100/Condensate[[#This Row],[รวมยอดใช้สตีม]]/100,0) -> 0.51037851 | P11: =SUM(Condensate[[#This Row],[ยอดการใช้ Steam BHS]:[ยอดการใช้ Steam YUELI]]) -> 81.9
A12: ='[2]1.บาทต่อการผลิต'!A14 -> 45911 | B12: =VLOOKUP(Condensate[[#This Row],[วันที่]],'[3]TABLE DATA'!$V:$W,2,0) -> 19 | C12: =[2]มิเตอร์น้ำ!AT13 -> 86 | D12: =Condensate[[#This Row],[มิเตอร์น้ำ Boiler]]-Condensate[[#This Row],[Soft Mark Up]] -> 67 | E12: =E11 -> 0.8 | F12: =IFERROR(Condensate[[#This Row],[น้ำ CONDENSATE กลับ]]/Condensate[[#This Row],[รวมยอดใช้สตีม]],0) -> 0.85677749 | G12: =(Condensate[[#This Row],[% condensate ]]-Condensate[[#This Row],[Target]])/80*100 -> 0.070971867 | H12: =IFERROR(Condensate[[#This Row],[ยอดการใช้ Steam BHS]]*Condensate[[#This Row],[น้ำ CONDENSATE กลับ]]/Condensate[[#This Row],[มิเตอร์น้ำ Boiler]],0) -> 31.786047 | I12: =IFERROR(Condensate[[#This Row],[CON Return bhs]]/Condensate[[#This Row],[ยอดการใช้ Steam BHS]],0) -> 0.77906977 | J12: =IFERROR(Condensate[[#This Row],[ยอดการใช้ Steam YUELI]]*Condensate[[#This Row],[น้ำ CONDENSATE กลับ]]/Condensate[[#This Row],[มิเตอร์น้ำ Boiler]],0) -> 29.137209 | K12: =IFERROR(Condensate[[#This Row],[CON Return yueli]]/Condensate[[#This Row],[ยอดการใช้ Steam YUELI]],0) -> 0.77906977 | L12: ='[2]ข้อมูลตัด ถ่านหิน'!C16 -> 40.8 | M12: ='[2]ข้อมูลตัด ถ่านหิน'!D16 -> 37.4 | N12: =IFERROR(Condensate[[#This Row],[ยอดการใช้ Steam BHS]]*100/Condensate[[#This Row],[รวมยอดใช้สตีม]]/100,0) -> 0.52173913 | O12: =IFERROR(Condensate[[#This Row],[ยอดการใช้ Steam YUELI]]*100/Condensate[[#This Row],[รวมยอดใช้สตีม]]/100,0) -> 0.47826087 | P12: =SUM(Condensate[[#This Row],[ยอดการใช้ Steam BHS]:[ยอดการใช้ Steam YUELI]]) -> 78.2
A13: ='[2]1.บาทต่อการผลิต'!A15 -> 45912 | B13: =VLOOKUP(Condensate[[#This Row],[วันที่]],'[3]TABLE DATA'!$V:$W,2,0) -> 19 | C13: =[2]มิเตอร์น้ำ!AT14 -> 86 | D13: =Condensate[[#This Row],[มิเตอร์น้ำ Boiler]]-Condensate[[#This Row],[Soft Mark Up]] -> 67 | E13: =E12 -> 0.8 | F13: =IFERROR(Condensate[[#This Row],[น้ำ CONDENSATE กลับ]]/Condensate[[#This Row],[รวมยอดใช้สตีม]],0) -> 0.8427673 | G13: =(Condensate[[#This Row],[% condensate ]]-Condensate[[#This Row],[Target]])/80*100 -> 0.053459119 | H13: =IFERROR(Condensate[[#This Row],[ยอดการใช้ Steam BHS]]*Condensate[[#This Row],[น้ำ CONDENSATE กลับ]]/Condensate[[#This Row],[มิเตอร์น้ำ Boiler]],0) -> 31.786047 | I13: =IFERROR(Condensate[[#This Row],[CON Return bhs]]/Condensate[[#This Row],[ยอดการใช้ Steam BHS]],0) -> 0.77906977 | J13: =IFERROR(Condensate[[#This Row],[ยอดการใช้ Steam YUELI]]*Condensate[[#This Row],[น้ำ CONDENSATE กลับ]]/Condensate[[#This Row],[มิเตอร์น้ำ Boiler]],0) -> 30.15 | K13: =IFERROR(Condensate[[#This Row],[CON Return yueli]]/Condensate[[#This Row],[ยอดการใช้ Steam YUELI]],0) -> 0.77906977 | L13: ='[2]ข้อมูลตัด ถ่านหิน'!C17 -> 40.8 | M13: ='[2]ข้อมูลตัด ถ่านหิน'!D17 -> 38.7 | N13: =IFERROR(Condensate[[#This Row],[ยอดการใช้ Steam BHS]]*100/Condensate[[#This Row],[รวมยอดใช้สตีม]]/100,0) -> 0.51320755 | O13: =IFERROR(Condensate[[#This Row],[ยอดการใช้ Steam YUELI]]*100/Condensate[[#This Row],[รวมยอดใช้สตีม]]/100,0) -> 0.48679245 | P13: =SUM(Condensate[[#This Row],[ยอดการใช้ Steam BHS]:[ยอดการใช้ Steam YUELI]]) -> 79.5
A14: ='[2]1.บาทต่อการผลิต'!A16 -> 45913 | B14: =VLOOKUP(Condensate[[#This Row],[วันที่]],'[3]TABLE DATA'!$V:$W,2,0) -> 19 | C14: =[2]มิเตอร์น้ำ!AT15 -> 100 | D14: =Condensate[[#This Row],[มิเตอร์น้ำ Boiler]]-Condensate[[#This Row],[Soft Mark Up]] -> 81 | E14: =E13 -> 0.8 | F14: =IFERROR(Condensate[[#This Row],[น้ำ CONDENSATE กลับ]]/Condensate[[#This Row],[รวมยอดใช้สตีม]],0) -> 0.88043478 | G14: =(Condensate[[#This Row],[% condensate ]]-Condensate[[#This Row],[Target]])/80*100 -> 0.10054348 | H14: =IFERROR(Condensate[[#This Row],[ยอดการใช้ Steam BHS]]*Condensate[[#This Row],[น้ำ CONDENSATE กลับ]]/Condensate[[#This Row],[มิเตอร์น้ำ Boiler]],0) -> 32.319 | I14: =IFERROR(Condensate[[#This Row],[CON Return bhs]]/Condensate[[#This Row],[ยอดการใช้ Steam BHS]],0) -> 0.81 | J14: =IFERROR(Condensate[[#This Row],[ยอดการใช้ Steam YUELI]]*Condensate[[#This Row],[น้ำ CONDENSATE กลับ]]/Condensate[[#This Row],[มิเตอร์น้ำ Boiler]],0) -> 42.201 | K14: =IFERROR(Condensate[[#This Row],[CON Return yueli]]/Condensate[[#This Row],[ยอดการใช้ Steam YUELI]],0) -> 0.81 | L14: ='[2]ข้อมูลตัด ถ่านหิน'!C18 -> 39.9 | M14: ='[2]ข้อมูลตัด ถ่านหิน'!D18 -> 52.1 | N14: =IFERROR(Condensate[[#This Row],[ยอดการใช้ Steam BHS]]*100/Condensate[[#This Row],[รวมยอดใช้สตีม]]/100,0) -> 0.43369565 | O14: =IFERROR(Condensate[[#This Row],[ยอดการใช้ Steam YUELI]]*100/Condensate[[#This Row],[รวมยอดใช้สตีม]]/100,0) -> 0.56630435 | P14: =SUM(Condensate[[#This Row],[ยอดการใช้ Steam BHS]:[ยอดการใช้ Steam YUELI]]) -> 92
... A31: ='[2]1.บาทต่อการผลิต'!A33 -> 45930 | B31: =VLOOKUP(Condensate[[#This Row],[วันที่]],'[3]TABLE DATA'!$V:$W,2,0) -> 17 | C31: =[2]มิเตอร์น้ำ!AT32 -> 93 | D31: =Condensate[[#This Row],[มิเตอร์น้ำ Boiler]]-Condensate[[#This Row],[Soft Mark Up]] -> 76 | E31: =E30 -> 0.8 | F31: =IFERROR(Condensate[[#This Row],[น้ำ CONDENSATE กลับ]]/Condensate[[#This Row],[รวมยอดใช้สตีม]],0) -> 0.75697211 | G31: =(Condensate[[#This Row],[% condensate ]]-Condensate[[#This Row],[Target]])/80*100 -> -0.053784861 | H31: =IFERROR(Condensate[[#This Row],[ยอดการใช้ Steam BHS]]*Condensate[[#This Row],[น้ำ CONDENSATE กลับ]]/Condensate[[#This Row],[มิเตอร์น้ำ Boiler]],0) -> 35.139785 | I31: =IFERROR(Condensate[[#This Row],[CON Return bhs]]/Condensate[[#This Row],[ยอดการใช้ Steam BHS]],0) -> 0.8172043 | J31: =IFERROR(Condensate[[#This Row],[ยอดการใช้ Steam YUELI]]*Condensate[[#This Row],[น้ำ CONDENSATE กลับ]]/Condensate[[#This Row],[มิเตอร์น้ำ Boiler]],0) -> 46.907527 | K31: =IFERROR(Condensate[[#This Row],[CON Return yueli]]/Condensate[[#This Row],[ยอดการใช้ Steam YUELI]],0) -> 0.8172043 | L31: ='[2]ข้อมูลตัด ถ่านหิน'!C35 -> 43 | M31: ='[2]ข้อมูลตัด ถ่านหิน'!D35 -> 57.4 | N31: =IFERROR(Condensate[[#This Row],[ยอดการใช้ Steam BHS]]*100/Condensate[[#This Row],[รวมยอดใช้สตีม]]/100,0) -> 0.42828685 | O31: =IFERROR(Condensate[[#This Row],[ยอดการใช้ Steam YUELI]]*100/Condensate[[#This Row],[รวมยอดใช้สตีม]]/100,0) -> 0.57171315 | P31: =SUM(Condensate[[#This Row],[ยอดการใช้ Steam BHS]:[ยอดการใช้ Steam YUELI]]) -> 100.4
A32: 45931 | B32: =VLOOKUP(Condensate[[#This Row],[วันที่]],'[4]TABLE DATA'!$V:$W,2,0) -> 19 | C32: =[5]มิเตอร์น้ำ!AY3 -> 93 | D32: =Condensate[[#This Row],[มิเตอร์น้ำ Boiler]]-Condensate[[#This Row],[Soft Mark Up]] -> 74 | E32: =E31 -> 0.8 | F32: =IFERROR(Condensate[[#This Row],[น้ำ CONDENSATE กลับ]]/Condensate[[#This Row],[รวมยอดใช้สตีม]],0) -> 0.67827681 | G32: =(Condensate[[#This Row],[% condensate ]]-Condensate[[#This Row],[Target]])/80*100 -> -0.15215399 | H32: =IFERROR(Condensate[[#This Row],[ยอดการใช้ Steam BHS]]*Condensate[[#This Row],[น้ำ CONDENSATE กลับ]]/Condensate[[#This Row],[มิเตอร์น้ำ Boiler]],0) -> 32.623656 | I32: =IFERROR(Condensate[[#This Row],[CON Return bhs]]/Condensate[[#This Row],[ยอดการใช้ Steam BHS]],0) -> 0.79569892 | J32: =IFERROR(Condensate[[#This Row],[ยอดการใช้ Steam YUELI]]*Condensate[[#This Row],[น้ำ CONDENSATE กลับ]]/Condensate[[#This Row],[มิเตอร์น้ำ Boiler]],0) -> 54.187097 | K32: =IFERROR(Condensate[[#This Row],[CON Return yueli]]/Condensate[[#This Row],[ยอดการใช้ Steam YUELI]],0) -> 0.79569892 | L32: ='[5]ข้อมูลตัด ถ่านหิน'!C6 -> 41 | M32: ='[5]ข้อมูลตัด ถ่านหิน'!D6 -> 68.1 | N32: =IFERROR(Condensate[[#This Row],[ยอดการใช้ Steam BHS]]*100/Condensate[[#This Row],[รวมยอดใช้สตีม]]/100,0) -> 0.37580202 | O32: =IFERROR(Condensate[[#This Row],[ยอดการใช้ Steam YUELI]]*100/Condensate[[#This Row],[รวมยอดใช้สตีม]]/100,0) -> 0.62419798 | P32: =SUM(Condensate[[#This Row],[ยอดการใช้ Steam BHS]:[ยอดการใช้ Steam YUELI]]) -> 109.1
A33: 45932 | B33: =VLOOKUP(Condensate[[#This Row],[วันที่]],'[4]TABLE DATA'!$V:$W,2,0) -> 25 | C33: =[5]มิเตอร์น้ำ!AY4 -> 100 | D33: =Condensate[[#This Row],[มิเตอร์น้ำ Boiler]]-Condensate[[#This Row],[Soft Mark Up]] -> 75 | E33: =E32 -> 0.8 | F33: =IFERROR(Condensate[[#This Row],[น้ำ CONDENSATE กลับ]]/Condensate[[#This Row],[รวมยอดใช้สตีม]],0) -> 0.7183908 | G33: =(Condensate[[#This Row],[% condensate ]]-Condensate[[#This Row],[Target]])/80*100 -> -0.10201149 | H33: =IFERROR(Condensate[[#This Row],[ยอดการใช้ Steam BHS]]*Condensate[[#This Row],[น้ำ CONDENSATE กลับ]]/Condensate[[#This Row],[มิเตอร์น้ำ Boiler]],0) -> 32.175 | I33: =IFERROR(Condensate[[#This Row],[CON Return bhs]]/Condensate[[#This Row],[ยอดการใช้ Steam BHS]],0) -> 0.75 | J33: =IFERROR(Condensate[[#This Row],[ยอดการใช้ Steam YUELI]]*Condensate[[#This Row],[น้ำ CONDENSATE กลับ]]/Condensate[[#This Row],[มิเตอร์น้ำ Boiler]],0) -> 46.125 | K33: =IFERROR(Condensate[[#This Row],[CON Return yueli]]/Condensate[[#This Row],[ยอดการใช้ Steam YUELI]],0) -> 0.75 | L33: ='[5]ข้อมูลตัด ถ่านหิน'!C7 -> 42.9 | M33: ='[5]ข้อมูลตัด ถ่านหิน'!D7 -> 61.5 | N33: =IFERROR(Condensate[[#This Row],[ยอดการใช้ Steam BHS]]*100/Condensate[[#This Row],[รวมยอดใช้สตีม]]/100,0) -> 0.41091954 | O33: =IFERROR(Condensate[[#This Row],[ยอดการใช้ Steam YUELI]]*100/Condensate[[#This Row],[รวมยอดใช้สตีม]]/100,0) -> 0.58908046 | P33: =SUM(Condensate[[#This Row],[ยอดการใช้ Steam BHS]:[ยอดการใช้ Steam YUELI]]) -> 104.4
A34: 45933 | B34: =VLOOKUP(Condensate[[#This Row],[วันที่]],'[4]TABLE DATA'!$V:$W,2,0) -> 22 | C34: =[5]มิเตอร์น้ำ!AY5 -> 98 | D34: =Condensate[[#This Row],[มิเตอร์น้ำ Boiler]]-Condensate[[#This Row],[Soft Mark Up]] -> 76 | E34: =E33 -> 0.8 | F34: =IFERROR(Condensate[[#This Row],[น้ำ CONDENSATE กลับ]]/Condensate[[#This Row],[รวมยอดใช้สตีม]],0) -> 0.77630235 | G34: =(Condensate[[#This Row],[% condensate ]]-Condensate[[#This Row],[Target]])/80*100 -> -0.029622063 | H34: =IFERROR(Condensate[[#This Row],[ยอดการใช้ Steam BHS]]*Condensate[[#This Row],[น้ำ CONDENSATE กลับ]]/Condensate[[#This Row],[มิเตอร์น้ำ Boiler]],0) -> 32.416327 | I34: =IFERROR(Condensate[[#This Row],[CON Return bhs]]/Condensate[[#This Row],[ยอดการใช้ Steam BHS]],0) -> 0.7755102 | J34: =IFERROR(Condensate[[#This Row],[ยอดการใช้ Steam YUELI]]*Condensate[[#This Row],[น้ำ CONDENSATE กลับ]]/Condensate[[#This Row],[มิเตอร์น้ำ Boiler]],0) -> 43.506122 | K34: =IFERROR(Condensate[[#This Row],[CON Return yueli]]/Condensate[[#This Row],[ยอดการใช้ Steam YUELI]],0) -> 0.7755102 | L34: ='[5]ข้อมูลตัด ถ่านหิน'!C8 -> 41.8 | M34: ='[5]ข้อมูลตัด ถ่านหิน'!D8 -> 56.1 | N34: =IFERROR(Condensate[[#This Row],[ยอดการใช้ Steam BHS]]*100/Condensate[[#This Row],[รวมยอดใช้สตีม]]/100,0) -> 0.42696629 | O34: =IFERROR(Condensate[[#This Row],[ยอดการใช้ Steam YUELI]]*100/Condensate[[#This Row],[รวมยอดใช้สตีม]]/100,0) -> 0.57303371 | P34: =SUM(Condensate[[#This Row],[ยอดการใช้ Steam BHS]:[ยอดการใช้ Steam YUELI]]) -> 97.9
A35: 45934 | B35: =VLOOKUP(Condensate[[#This Row],[วันที่]],'[4]TABLE DATA'!$V:$W,2,0) -> 19 | C35: =[5]มิเตอร์น้ำ!AY6 -> 96 | D35: =Condensate[[#This Row],[มิเตอร์น้ำ Boiler]]-Condensate[[#This Row],[Soft Mark Up]] -> 77 | E35: =E34 -> 0.8 | F35: =IFERROR(Condensate[[#This Row],[น้ำ CONDENSATE กลับ]]/Condensate[[#This Row],[รวมยอดใช้สตีม]],0) -> 0.73896353 | G35: =(Condensate[[#This Row],[% condensate ]]-Condensate[[#This Row],[Target]])/80*100 -> -0.076295585 | H35: =IFERROR(Condensate[[#This Row],[ยอดการใช้ Steam BHS]]*Condensate[[#This Row],[น้ำ CONDENSATE กลับ]]/Condensate[[#This Row],[มิเตอร์น้ำ Boiler]],0) -> 32.885417 | I35: =IFERROR(Condensate[[#This Row],[CON Return bhs]]/Condensate[[#This Row],[ยอดการใช้ Steam BHS]],0) -> 0.80208333 | J35: =IFERROR(Condensate[[#This Row],[ยอดการใช้ Steam YUELI]]*Condensate[[#This Row],[น้ำ CONDENSATE กลับ]]/Condensate[[#This Row],[มิเตอร์น้ำ Boiler]],0) -> 50.691667 | K35: =IFERROR(Condensate[[#This Row],[CON Return yueli]]/Condensate[[#This Row],[ยอดการใช้ Steam YUELI]],0) -> 0.80208333 | L35: ='[5]ข้อมูลตัด ถ่านหิน'!C9 -> 41 | M35: ='[5]ข้อมูลตัด ถ่านหิน'!D9 -> 63.2 | N35: =IFERROR(Condensate[[#This Row],[ยอดการใช้ Steam BHS]]*100/Condensate[[#This Row],[รวมยอดใช้สตีม]]/100,0) -> 0.39347409 | O35: =IFERROR(Condensate[[#This Row],[ยอดการใช้ Steam YUELI]]*100/Condensate[[#This Row],[รวมยอดใช้สตีม]]/100,0) -> 0.60652591 | P35: =SUM(Condensate[[#This Row],[ยอดการใช้ Steam BHS]:[ยอดการใช้ Steam YUELI]]) -> 104.2
A36: 45935 | B36: =VLOOKUP(Condensate[[#This Row],[วันที่]],'[4]TABLE DATA'!$V:$W,2,0) -> 20 | C36: =[5]มิเตอร์น้ำ!AY7 -> 65 | D36: =Condensate[[#This Row],[มิเตอร์น้ำ Boiler]]-Condensate[[#This Row],[Soft Mark Up]] -> 45 | E36: =E35 -> 0.8 | F36: =IFERROR(Condensate[[#This Row],[น้ำ CONDENSATE กลับ]]/Condensate[[#This Row],[รวมยอดใช้สตีม]],0) -> 0.73529412 | G36: =(Condensate[[#This Row],[% condensate ]]-Condensate[[#This Row],[Target]])/80*100 -> -0.080882353 | H36: =IFERROR(Condensate[[#This Row],[ยอดการใช้ Steam BHS]]*Condensate[[#This Row],[น้ำ CONDENSATE กลับ]]/Condensate[[#This Row],[มิเตอร์น้ำ Boiler]],0) -> 21.046154 | I36: =IFERROR(Condensate[[#This Row],[CON Return bhs]]/Condensate[[#This Row],[ยอดการใช้ Steam BHS]],0) -> 0.69230769 | J36: =IFERROR(Condensate[[#This Row],[ยอดการใช้ Steam YUELI]]*Condensate[[#This Row],[น้ำ CONDENSATE กลับ]]/Condensate[[#This Row],[มิเตอร์น้ำ Boiler]],0) -> 21.323077 | K36: =IFERROR(Condensate[[#This Row],[CON Return yueli]]/Condensate[[#This Row],[ยอดการใช้ Steam YUELI]],0) -> 0.69230769 | L36: ='[5]ข้อมูลตัด ถ่านหิน'!C10 -> 30.4 | M36: ='[5]ข้อมูลตัด ถ่านหิน'!D10 -> 30.8 | N36: =IFERROR(Condensate[[#This Row],[ยอดการใช้ Steam BHS]]*100/Condensate[[#This Row],[รวมยอดใช้สตีม]]/100,0) -> 0.49673203 | O36: =IFERROR(Condensate[[#This Row],[ยอดการใช้ Steam YUELI]]*100/Condensate[[#This Row],[รวมยอดใช้สตีม]]/100,0) -> 0.50326797 | P36: =SUM(Condensate[[#This Row],[ยอดการใช้ Steam BHS]:[ยอดการใช้ Steam YUELI]]) -> 61.2
A37: 45936 | B37: =VLOOKUP(Condensate[[#This Row],[วันที่]],'[4]TABLE DATA'!$V:$W,2,0) -> 11 | C37: =[5]มิเตอร์น้ำ!AY8 -> 65 | D37: =Condensate[[#This Row],[มิเตอร์น้ำ Boiler]]-Condensate[[#This Row],[Soft Mark Up]] -> 54 | E37: =E36 -> 0.8 | F37: =IFERROR(Condensate[[#This Row],[น้ำ CONDENSATE กลับ]]/Condensate[[#This Row],[รวมยอดใช้สตีม]],0) -> 0.8490566 | G37: =(Condensate[[#This Row],[% condensate ]]-Condensate[[#This Row],[Target]])/80*100 -> 0.061320755 | H37: =IFERROR(Condensate[[#This Row],[ยอดการใช้ Steam BHS]]*Condensate[[#This Row],[น้ำ CONDENSATE กลับ]]/Condensate[[#This Row],[มิเตอร์น้ำ Boiler]],0) -> 25.255385 | I37: =IFERROR(Condensate[[#This Row],[CON Return bhs]]/Condensate[[#This Row],[ยอดการใช้ Steam BHS]],0) -> 0.83076923 | J37: =IFERROR(Condensate[[#This Row],[ยอดการใช้ Steam YUELI]]*Condensate[[#This Row],[น้ำ CONDENSATE กลับ]]/Condensate[[#This Row],[มิเตอร์น้ำ Boiler]],0) -> 27.581538 | K37: =IFERROR(Condensate[[#This Row],[CON Return yueli]]/Condensate[[#This Row],[ยอดการใช้ Steam YUELI]],0) -> 0.83076923 | L37: ='[5]ข้อมูลตัด ถ่านหิน'!C11 -> 30.4 | M37: ='[5]ข้อมูลตัด ถ่านหิน'!D11 -> 33.2 | N37: =IFERROR(Condensate[[#This Row],[ยอดการใช้ Steam BHS]]*100/Condensate[[#This Row],[รวมยอดใช้สตีม]]/100,0) -> 0.47798742 | O37: =IFERROR(Condensate[[#This Row],[ยอดการใช้ Steam YUELI]]*100/Condensate[[#This Row],[รวมยอดใช้สตีม]]/100,0) -> 0.52201258 | P37: =SUM(Condensate[[#This Row],[ยอดการใช้ Steam BHS]:[ยอดการใช้ Steam YUELI]]) -> 63.6
A38: 45937 | B38: =VLOOKUP(Condensate[[#This Row],[วันที่]],'[4]TABLE DATA'!$V:$W,2,0) -> 23 | C38: =[5]มิเตอร์น้ำ!AY9 -> 86 | D38: =Condensate[[#This Row],[มิเตอร์น้ำ Boiler]]-Condensate[[#This Row],[Soft Mark Up]] -> 63 | E38: =E37 -> 0.8 | F38: =IFERROR(Condensate[[#This Row],[น้ำ CONDENSATE กลับ]]/Condensate[[#This Row],[รวมยอดใช้สตีม]],0) -> 0.71106095 | G38: =(Condensate[[#This Row],[% condensate ]]-Condensate[[#This Row],[Target]])/80*100 -> -0.11117381 | H38: =IFERROR(Condensate[[#This Row],[ยอดการใช้ Steam BHS]]*Condensate[[#This Row],[น้ำ CONDENSATE กลับ]]/Condensate[[#This Row],[มิเตอร์น้ำ Boiler]],0) -> 30.10814 | I38: =IFERROR(Condensate[[#This Row],[CON Return bhs]]/Condensate[[#This Row],[ยอดการใช้ Steam BHS]],0) -> 0.73255814 | J38: =IFERROR(Condensate[[#This Row],[ยอดการใช้ Steam YUELI]]*Condensate[[#This Row],[น้ำ CONDENSATE กลับ]]/Condensate[[#This Row],[มิเตอร์น้ำ Boiler]],0) -> 34.796512 | K38: =IFERROR(Condensate[[#This Row],[CON Return yueli]]/Condensate[[#This Row],[ยอดการใช้ Steam YUELI]],0) -> 0.73255814 | L38: ='[5]ข้อมูลตัด ถ่านหิน'!C12 -> 41.1 | M38: ='[5]ข้อมูลตัด ถ่านหิน'!D12 -> 47.5 | N38: =IFERROR(Condensate[[#This Row],[ยอดการใช้ Steam BHS]]*100/Condensate[[#This Row],[รวมยอดใช้สตีม]]/100,0) -> 0.46388262 | O38: =IFERROR(Condensate[[#This Row],[ยอดการใช้ Steam YUELI]]*100/Condensate[[#This Row],[รวมยอดใช้สตีม]]/100,0) -> 0.53611738 | P38: =SUM(Condensate[[#This Row],[ยอดการใช้ Steam BHS]:[ยอดการใช้ Steam YUELI]]) -> 88.6
A39: 45938 | B39: =VLOOKUP(Condensate[[#This Row],[วันที่]],'[4]TABLE DATA'!$V:$W,2,0) -> 24 | C39: =[5]มิเตอร์น้ำ!AY10 -> 91 | D39: =Condensate[[#This Row],[มิเตอร์น้ำ Boiler]]-Condensate[[#This Row],[Soft Mark Up]] -> 67 | E39: =E38 -> 0.8 | F39: =IFERROR(Condensate[[#This Row],[น้ำ CONDENSATE กลับ]]/Condensate[[#This Row],[รวมยอดใช้สตีม]],0) -> 0.74944072 | G39: =(Condensate[[#This Row],[% condensate ]]-Condensate[[#This Row],[Target]])/80*100 -> -0.063199105 | H39: =IFERROR(Condensate[[#This Row],[ยอดการใช้ Steam BHS]]*Condensate[[#This Row],[น้ำ CONDENSATE กลับ]]/Condensate[[#This Row],[มิเตอร์น้ำ Boiler]],0) -> 31.07033 | I39: =IFERROR(Condensate[[#This Row],[CON Return bhs]]/Condensate[[#This Row],[ยอดการใช้ Steam BHS]],0) -> 0.73626374 | J39: =IFERROR(Condensate[[#This Row],[ยอดการใช้ Steam YUELI]]*Condensate[[#This Row],[น้ำ CONDENSATE กลับ]]/Condensate[[#This Row],[มิเตอร์น้ำ Boiler]],0) -> 34.751648 | K39: =IFERROR(Condensate[[#This Row],[CON Return yueli]]/Condensate[[#This Row],[ยอดการใช้ Steam YUELI]],0) -> 0.73626374 | L39: ='[5]ข้อมูลตัด ถ่านหิน'!C13 -> 42.2 | M39: ='[5]ข้อมูลตัด ถ่านหิน'!D13 -> 47.2 | N39: =IFERROR(Condensate[[#This Row],[ยอดการใช้ Steam BHS]]*100/Condensate[[#This Row],[รวมยอดใช้สตีม]]/100,0) -> 0.47203579 | O39: =IFERROR(Condensate[[#This Row],[ยอดการใช้ Steam YUELI]]*100/Condensate[[#This Row],[รวมยอดใช้สตีม]]/100,0) -> 0.52796421 | P39: =SUM(Condensate[[#This Row],[ยอดการใช้ Steam BHS]:[ยอดการใช้ Steam YUELI]]) -> 89.4
A40: 45939 | B40: =VLOOKUP(Condensate[[#This Row],[วันที่]],'[4]TABLE DATA'!$V:$W,2,0) -> 23 | C40: =[5]มิเตอร์น้ำ!AY11 -> 104 | D40: =Condensate[[#This Row],[มิเตอร์น้ำ Boiler]]-Condensate[[#This Row],[Soft Mark Up]] -> 81 | E40: =E39 -> 0.8 | F40: =IFERROR(Condensate[[#This Row],[น้ำ CONDENSATE กลับ]]/Condensate[[#This Row],[รวมยอดใช้สตีม]],0) -> 0.7956778 | G40: =(Condensate[[#This Row],[% condensate ]]-Condensate[[#This Row],[Target]])/80*100 -> -0.0054027505 | H40: =IFERROR(Condensate[[#This Row],[ยอดการใช้ Steam BHS]]*Condensate[[#This Row],[น้ำ CONDENSATE กลับ]]/Condensate[[#This Row],[มิเตอร์น้ำ Boiler]],0) -> 33.256731 | I40: =IFERROR(Condensate[[#This Row],[CON Return bhs]]/Condensate[[#This Row],[ยอดการใช้ Steam BHS]],0) -> 0.77884615 | J40: =IFERROR(Condensate[[#This Row],[ยอดการใช้ Steam YUELI]]*Condensate[[#This Row],[น้ำ CONDENSATE กลับ]]/Condensate[[#This Row],[มิเตอร์น้ำ Boiler]],0) -> 46.029808 | K40: =IFERROR(Condensate[[#This Row],[CON Return yueli]]/Condensate[[#This Row],[ยอดการใช้ Steam YUELI]],0) -> 0.77884615 | L40: ='[5]ข้อมูลตัด ถ่านหิน'!C14 -> 42.7 | M40: ='[5]ข้อมูลตัด ถ่านหิน'!D14 -> 59.1 | N40: =IFERROR(Condensate[[#This Row],[ยอดการใช้ Steam BHS]]*100/Condensate[[#This Row],[รวมยอดใช้สตีม]]/100,0) -> 0.4194499 | O40: =IFERROR(Condensate[[#This Row],[ยอดการใช้ Steam YUELI]]*100/Condensate[[#This Row],[รวมยอดใช้สตีม]]/100,0) -> 0.5805501 | P40: =SUM(Condensate[[#This Row],[ยอดการใช้ Steam BHS]:[ยอดการใช้ Steam YUELI]]) -> 101.8
A41: 45940 | B41: =VLOOKUP(Condensate[[#This Row],[วันที่]],'[4]TABLE DATA'!$V:$W,2,0) -> 26 | C41: =[5]มิเตอร์น้ำ!AY12 -> 88 | D41: =Condensate[[#This Row],[มิเตอร์น้ำ Boiler]]-Condensate[[#This Row],[Soft Mark Up]] -> 62 | E41: =E40 -> 0.8 | F41: =IFERROR(Condensate[[#This Row],[น้ำ CONDENSATE กลับ]]/Condensate[[#This Row],[รวมยอดใช้สตีม]],0) -> 0.72093023 | G41: =(Condensate[[#This Row],[% condensate ]]-Condensate[[#This Row],[Target]])/80*100 -> -0.098837209 | H41: =IFERROR(Condensate[[#This Row],[ยอดการใช้ Steam BHS]]*Condensate[[#This Row],[น้ำ CONDENSATE กลับ]]/Condensate[[#This Row],[มิเตอร์น้ำ Boiler]],0) -> 29.45 | I41: =IFERROR(Condensate[[#This Row],[CON Return bhs]]/Condensate[[#This Row],[ยอดการใช้ Steam BHS]],0) -> 0.70454545 | J41: =IFERROR(Condensate[[#This Row],[ยอดการใช้ Steam YUELI]]*Condensate[[#This Row],[น้ำ CONDENSATE กลับ]]/Condensate[[#This Row],[มิเตอร์น้ำ Boiler]],0) -> 31.140909 | K41: =IFERROR(Condensate[[#This Row],[CON Return yueli]]/Condensate[[#This Row],[ยอดการใช้ Steam YUELI]],0) -> 0.70454545 | L41: ='[5]ข้อมูลตัด ถ่านหิน'!C15 -> 41.8 | M41: ='[5]ข้อมูลตัด ถ่านหิน'!D15 -> 44.2 | N41: =IFERROR(Condensate[[#This Row],[ยอดการใช้ Steam BHS]]*100/Condensate[[#This Row],[รวมยอดใช้สตีม]]/100,0) -> 0.48604651 | O41: =IFERROR(Condensate[[#This Row],[ยอดการใช้ Steam YUELI]]*100/Condensate[[#This Row],[รวมยอดใช้สตีม]]/100,0) -> 0.51395349 | P41: =SUM(Condensate[[#This Row],[ยอดการใช้ Steam BHS]:[ยอดการใช้ Steam YUELI]]) -> 86
A42: 45941 | B42: =VLOOKUP(Condensate[[#This Row],[วันที่]],'[4]TABLE DATA'!$V:$W,2,0) -> 21 | C42: =[5]มิเตอร์น้ำ!AY13 -> 103 | D42: =Condensate[[#This Row],[มิเตอร์น้ำ Boiler]]-Condensate[[#This Row],[Soft Mark Up]] -> 82 | E42: =E41 -> 0.8 | F42: =IFERROR(Condensate[[#This Row],[น้ำ CONDENSATE กลับ]]/Condensate[[#This Row],[รวมยอดใช้สตีม]],0) -> 0.80392157 | G42: =(Condensate[[#This Row],[% condensate ]]-Condensate[[#This Row],[Target]])/80*100 -> 0.0049019608 | H42: =IFERROR(Condensate[[#This Row],[ยอดการใช้ Steam BHS]]*Condensate[[#This Row],[น้ำ CONDENSATE กลับ]]/Condensate[[#This Row],[มิเตอร์น้ำ Boiler]],0) -> 33.914563 | I42: =IFERROR(Condensate[[#This Row],[CON Return bhs]]/Condensate[[#This Row],[ยอดการใช้ Steam BHS]],0) -> 0.7961165 | J42: =IFERROR(Condensate[[#This Row],[ยอดการใช้ Steam YUELI]]*Condensate[[#This Row],[น้ำ CONDENSATE กลับ]]/Condensate[[#This Row],[มิเตอร์น้ำ Boiler]],0) -> 47.28932 | K42: =IFERROR(Condensate[[#This Row],[CON Return yueli]]/Condensate[[#This Row],[ยอดการใช้ Steam YUELI]],0) -> 0.7961165 | L42: ='[5]ข้อมูลตัด ถ่านหิน'!C16 -> 42.6 | M42: ='[5]ข้อมูลตัด ถ่านหิน'!D16 -> 59.4 | N42: =IFERROR(Condensate[[#This Row],[ยอดการใช้ Steam BHS]]*100/Condensate[[#This Row],[รวมยอดใช้สตีม]]/100,0) -> 0.41764706 | O42: =IFERROR(Condensate[[#This Row],[ยอดการใช้ Steam YUELI]]*100/Condensate[[#This Row],[รวมยอดใช้สตีม]]/100,0) -> 0.58235294 | P42: =SUM(Condensate[[#This Row],[ยอดการใช้ Steam BHS]:[ยอดการใช้ Steam YUELI]]) -> 102
A43: 45942 | B43: =VLOOKUP(Condensate[[#This Row],[วันที่]],'[4]TABLE DATA'!$V:$W,2,0) -> 16 | C43: =[5]มิเตอร์น้ำ!AY14 -> 40 | D43: =Condensate[[#This Row],[มิเตอร์น้ำ Boiler]]-Condensate[[#This Row],[Soft Mark Up]] -> 24 | E43: =E42 -> 0.8 | F43: =IFERROR(Condensate[[#This Row],[น้ำ CONDENSATE กลับ]]/Condensate[[#This Row],[รวมยอดใช้สตีม]],0) -> 0.59405941 | G43: =(Condensate[[#This Row],[% condensate ]]-Condensate[[#This Row],[Target]])/80*100 -> -0.25742574 | H43: =IFERROR(Condensate[[#This Row],[ยอดการใช้ Steam BHS]]*Condensate[[#This Row],[น้ำ CONDENSATE กลับ]]/Condensate[[#This Row],[มิเตอร์น้ำ Boiler]],0) -> 10.08 | I43: =IFERROR(Condensate[[#This Row],[CON Return bhs]]/Condensate[[#This Row],[ยอดการใช้ Steam BHS]],0) -> 0.6 | J43: =IFERROR(Condensate[[#This Row],[ยอดการใช้ Steam YUELI]]*Condensate[[#This Row],[น้ำ CONDENSATE กลับ]]/Condensate[[#This Row],[มิเตอร์น้ำ Boiler]],0) -> 14.16 | K43: =IFERROR(Condensate[[#This Row],[CON Return yueli]]/Condensate[[#This Row],[ยอดการใช้ Steam YUELI]],0) -> 0.6 | L43: ='[5]ข้อมูลตัด ถ่านหิน'!C17 -> 16.8 | M43: ='[5]ข้อมูลตัด ถ่านหิน'!D17 -> 23.6 | N43: =IFERROR(Condensate[[#This Row],[ยอดการใช้ Steam BHS]]*100/Condensate[[#This Row],[รวมยอดใช้สตีม]]/100,0) -> 0.41584158 | O43: =IFERROR(Condensate[[#This Row],[ยอดการใช้ Steam YUELI]]*100/Condensate[[#This Row],[รวมยอดใช้สตีม]]/100,0) -> 0.58415842 | P43: =SUM(Condensate[[#This Row],[ยอดการใช้ Steam BHS]:[ยอดการใช้ Steam YUELI]]) -> 40.4
... A62: 45961 | B62: =VLOOKUP(Condensate[[#This Row],[วันที่]],'[4]TABLE DATA'!$V:$W,2,0) -> 21 | C62: =[5]มิเตอร์น้ำ!AY33 -> 104 | D62: =Condensate[[#This Row],[มิเตอร์น้ำ Boiler]]-Condensate[[#This Row],[Soft Mark Up]] -> 83 | E62: =E61 -> 0.8 | F62: =IFERROR(Condensate[[#This Row],[น้ำ CONDENSATE กลับ]]/Condensate[[#This Row],[รวมยอดใช้สตีม]],0) -> 0.78449905 | G62: =(Condensate[[#This Row],[% condensate ]]-Condensate[[#This Row],[Target]])/80*100 -> -0.019376181 | H62: =IFERROR(Condensate[[#This Row],[ยอดการใช้ Steam BHS]]*Condensate[[#This Row],[น้ำ CONDENSATE กลับ]]/Condensate[[#This Row],[มิเตอร์น้ำ Boiler]],0) -> 34.556731 | I62: =IFERROR(Condensate[[#This Row],[CON Return bhs]]/Condensate[[#This Row],[ยอดการใช้ Steam BHS]],0) -> 0.79807692 | J62: =IFERROR(Condensate[[#This Row],[ยอดการใช้ Steam YUELI]]*Condensate[[#This Row],[น้ำ CONDENSATE กลับ]]/Condensate[[#This Row],[มิเตอร์น้ำ Boiler]],0) -> 49.879808 | K62: =IFERROR(Condensate[[#This Row],[CON Return yueli]]/Condensate[[#This Row],[ยอดการใช้ Steam YUELI]],0) -> 0.79807692 | L62: ='[5]ข้อมูลตัด ถ่านหิน'!C36 -> 43.3 | M62: ='[5]ข้อมูลตัด ถ่านหิน'!D36 -> 62.5 | N62: =IFERROR(Condensate[[#This Row],[ยอดการใช้ Steam BHS]]*100/Condensate[[#This Row],[รวมยอดใช้สตีม]]/100,0) -> 0.40926276 | O62: =IFERROR(Condensate[[#This Row],[ยอดการใช้ Steam YUELI]]*100/Condensate[[#This Row],[รวมยอดใช้สตีม]]/100,0) -> 0.59073724 | P62: =SUM(Condensate[[#This Row],[ยอดการใช้ Steam BHS]:[ยอดการใช้ Steam YUELI]]) -> 105.8
A63: 45962 | B63: =VLOOKUP(Condensate[[#This Row],[วันที่]],'[6]TABLE DATA'!$V:$W,2,0) -> 22 | C63: =[7]มิเตอร์น้ำ!BD3 -> 91 | D63: =Condensate[[#This Row],[มิเตอร์น้ำ Boiler]]-Condensate[[#This Row],[Soft Mark Up]] -> 69 | E63: =E62 -> 0.8 | F63: =IFERROR(Condensate[[#This Row],[น้ำ CONDENSATE กลับ]]/Condensate[[#This Row],[รวมยอดใช้สตีม]],0) -> 0.7752809 | G63: =(Condensate[[#This Row],[% condensate ]]-Condensate[[#This Row],[Target]])/80*100 -> -0.030898876 | H63: =IFERROR(Condensate[[#This Row],[ยอดการใช้ Steam BHS]]*Condensate[[#This Row],[น้ำ CONDENSATE กลับ]]/Condensate[[#This Row],[มิเตอร์น้ำ Boiler]],0) -> 31.542857 | I63: =IFERROR(Condensate[[#This Row],[CON Return bhs]]/Condensate[[#This Row],[ยอดการใช้ Steam BHS]],0) -> 0.75824176 | J63: =IFERROR(Condensate[[#This Row],[ยอดการใช้ Steam YUELI]]*Condensate[[#This Row],[น้ำ CONDENSATE กลับ]]/Condensate[[#This Row],[มิเตอร์น้ำ Boiler]],0) -> 35.940659 | K63: =IFERROR(Condensate[[#This Row],[CON Return yueli]]/Condensate[[#This Row],[ยอดการใช้ Steam YUELI]],0) -> 0.75824176 | L63: ='[7]ข้อมูลตัด ถ่านหิน'!C6 -> 41.6 | M63: ='[7]ข้อมูลตัด ถ่านหิน'!D6 -> 47.4 | N63: =IFERROR(Condensate[[#This Row],[ยอดการใช้ Steam BHS]]*100/Condensate[[#This Row],[รวมยอดใช้สตีม]]/100,0) -> 0.46741573 | O63: =IFERROR(Condensate[[#This Row],[ยอดการใช้ Steam YUELI]]*100/Condensate[[#This Row],[รวมยอดใช้สตีม]]/100,0) -> 0.53258427 | P63: =SUM(Condensate[[#This Row],[ยอดการใช้ Steam BHS]:[ยอดการใช้ Steam YUELI]]) -> 89
A64: 45963 | B64: =VLOOKUP(Condensate[[#This Row],[วันที่]],'[6]TABLE DATA'!$V:$W,2,0) -> 17 | C64: =[7]มิเตอร์น้ำ!BD4 -> 60 | D64: =Condensate[[#This Row],[มิเตอร์น้ำ Boiler]]-Condensate[[#This Row],[Soft Mark Up]] -> 43 | E64: =E63 -> 0.8 | F64: =IFERROR(Condensate[[#This Row],[น้ำ CONDENSATE กลับ]]/Condensate[[#This Row],[รวมยอดใช้สตีม]],0) -> 0.73883162 | G64: =(Condensate[[#This Row],[% condensate ]]-Condensate[[#This Row],[Target]])/80*100 -> -0.076460481 | H64: =IFERROR(Condensate[[#This Row],[ยอดการใช้ Steam BHS]]*Condensate[[#This Row],[น้ำ CONDENSATE กลับ]]/Condensate[[#This Row],[มิเตอร์น้ำ Boiler]],0) -> 22.646667 | I64: =IFERROR(Condensate[[#This Row],[CON Return bhs]]/Condensate[[#This Row],[ยอดการใช้ Steam BHS]],0) -> 0.71666667 | J64: =IFERROR(Condensate[[#This Row],[ยอดการใช้ Steam YUELI]]*Condensate[[#This Row],[น้ำ CONDENSATE กลับ]]/Condensate[[#This Row],[มิเตอร์น้ำ Boiler]],0) -> 19.063333 | K64: =IFERROR(Condensate[[#This Row],[CON Return yueli]]/Condensate[[#This Row],[ยอดการใช้ Steam YUELI]],0) -> 0.71666667 | L64: ='[7]ข้อมูลตัด ถ่านหิน'!C7 -> 31.6 | M64: ='[7]ข้อมูลตัด ถ่านหิน'!D7 -> 26.6 | N64: =IFERROR(Condensate[[#This Row],[ยอดการใช้ Steam BHS]]*100/Condensate[[#This Row],[รวมยอดใช้สตีม]]/100,0) -> 0.54295533 | O64: =IFERROR(Condensate[[#This Row],[ยอดการใช้ Steam YUELI]]*100/Condensate[[#This Row],[รวมยอดใช้สตีม]]/100,0) -> 0.45704467 | P64: =SUM(Condensate[[#This Row],[ยอดการใช้ Steam BHS]:[ยอดการใช้ Steam YUELI]]) -> 58.2
A65: 45964 | B65: =VLOOKUP(Condensate[[#This Row],[วันที่]],'[6]TABLE DATA'!$V:$W,2,0) -> 6 | C65: =[7]มิเตอร์น้ำ!BD5 -> 68 | D65: =Condensate[[#This Row],[มิเตอร์น้ำ Boiler]]-Condensate[[#This Row],[Soft Mark Up]] -> 62 | E65: =E64 -> 0.8 | F65: =IFERROR(Condensate[[#This Row],[น้ำ CONDENSATE กลับ]]/Condensate[[#This Row],[รวมยอดใช้สตีม]],0) -> 0.94224924 | G65: =(Condensate[[#This Row],[% condensate ]]-Condensate[[#This Row],[Target]])/80*100 -> 0.17781155 | H65: =IFERROR(Condensate[[#This Row],[ยอดการใช้ Steam BHS]]*Condensate[[#This Row],[น้ำ CONDENSATE กลับ]]/Condensate[[#This Row],[มิเตอร์น้ำ Boiler]],0) -> 27.808824 | I65: =IFERROR(Condensate[[#This Row],[CON Return bhs]]/Condensate[[#This Row],[ยอดการใช้ Steam BHS]],0) -> 0.91176471 | J65: =IFERROR(Condensate[[#This Row],[ยอดการใช้ Steam YUELI]]*Condensate[[#This Row],[น้ำ CONDENSATE กลับ]]/Condensate[[#This Row],[มิเตอร์น้ำ Boiler]],0) -> 32.185294 | K65: =IFERROR(Condensate[[#This Row],[CON Return yueli]]/Condensate[[#This Row],[ยอดการใช้ Steam YUELI]],0) -> 0.91176471 | L65: ='[7]ข้อมูลตัด ถ่านหิน'!C8 -> 30.5 | M65: ='[7]ข้อมูลตัด ถ่านหิน'!D8 -> 35.3 | N65: =IFERROR(Condensate[[#This Row],[ยอดการใช้ Steam BHS]]*100/Condensate[[#This Row],[รวมยอดใช้สตีม]]/100,0) -> 0.46352584 | O65: =IFERROR(Condensate[[#This Row],[ยอดการใช้ Steam YUELI]]*100/Condensate[[#This Row],[รวมยอดใช้สตีม]]/100,0) -> 0.53647416 | P65: =SUM(Condensate[[#This Row],[ยอดการใช้ Steam BHS]:[ยอดการใช้ Steam YUELI]]) -> 65.8
A66: 45965 | B66: =VLOOKUP(Condensate[[#This Row],[วันที่]],'[6]TABLE DATA'!$V:$W,2,0) -> 18 | C66: =[7]มิเตอร์น้ำ!BD6 -> 97 | D66: =Condensate[[#This Row],[มิเตอร์น้ำ Boiler]]-Condensate[[#This Row],[Soft Mark Up]] -> 79 | E66: =E65 -> 0.8 | F66: =IFERROR(Condensate[[#This Row],[น้ำ CONDENSATE กลับ]]/Condensate[[#This Row],[รวมยอดใช้สตีม]],0) -> 0.74881517 | G66: =(Condensate[[#This Row],[% condensate ]]-Condensate[[#This Row],[Target]])/80*100 -> -0.063981043 | H66: =IFERROR(Condensate[[#This Row],[ยอดการใช้ Steam BHS]]*Condensate[[#This Row],[น้ำ CONDENSATE กลับ]]/Condensate[[#This Row],[มิเตอร์น้ำ Boiler]],0) -> 33.717526 | I66: =IFERROR(Condensate[[#This Row],[CON Return bhs]]/Condensate[[#This Row],[ยอดการใช้ Steam BHS]],0) -> 0.81443299 | J66: =IFERROR(Condensate[[#This Row],[ยอดการใช้ Steam YUELI]]*Condensate[[#This Row],[น้ำ CONDENSATE กลับ]]/Condensate[[#This Row],[มิเตอร์น้ำ Boiler]],0) -> 52.205155 | K66: =IFERROR(Condensate[[#This Row],[CON Return yueli]]/Condensate[[#This Row],[ยอดการใช้ Steam YUELI]],0) -> 0.81443299 | L66: ='[7]ข้อมูลตัด ถ่านหิน'!C9 -> 41.4 | M66: ='[7]ข้อมูลตัด ถ่านหิน'!D9 -> 64.1 | N66: =IFERROR(Condensate[[#This Row],[ยอดการใช้ Steam BHS]]*100/Condensate[[#This Row],[รวมยอดใช้สตีม]]/100,0) -> 0.39241706 | O66: =IFERROR(Condensate[[#This Row],[ยอดการใช้ Steam YUELI]]*100/Condensate[[#This Row],[รวมยอดใช้สตีม]]/100,0) -> 0.60758294 | P66: =SUM(Condensate[[#This Row],[ยอดการใช้ Steam BHS]:[ยอดการใช้ Steam YUELI]]) -> 105.5
A67: 45966 | B67: =VLOOKUP(Condensate[[#This Row],[วันที่]],'[6]TABLE DATA'!$V:$W,2,0) -> 18 | C67: =[7]มิเตอร์น้ำ!BD7 -> 84 | D67: =Condensate[[#This Row],[มิเตอร์น้ำ Boiler]]-Condensate[[#This Row],[Soft Mark Up]] -> 66 | E67: =E66 -> 0.8 | F67: =IFERROR(Condensate[[#This Row],[น้ำ CONDENSATE กลับ]]/Condensate[[#This Row],[รวมยอดใช้สตีม]],0) -> 0.79041916 | G67: =(Condensate[[#This Row],[% condensate ]]-Condensate[[#This Row],[Target]])/80*100 -> -0.011976048 | H67: =IFERROR(Condensate[[#This Row],[ยอดการใช้ Steam BHS]]*Condensate[[#This Row],[น้ำ CONDENSATE กลับ]]/Condensate[[#This Row],[มิเตอร์น้ำ Boiler]],0) -> 32.371429 | I67: =IFERROR(Condensate[[#This Row],[CON Return bhs]]/Condensate[[#This Row],[ยอดการใช้ Steam BHS]],0) -> 0.78571429 | J67: =IFERROR(Condensate[[#This Row],[ยอดการใช้ Steam YUELI]]*Condensate[[#This Row],[น้ำ CONDENSATE กลับ]]/Condensate[[#This Row],[มิเตอร์น้ำ Boiler]],0) -> 33.235714 | K67: =IFERROR(Condensate[[#This Row],[CON Return yueli]]/Condensate[[#This Row],[ยอดการใช้ Steam YUELI]],0) -> 0.78571429 | L67: ='[7]ข้อมูลตัด ถ่านหิน'!C10 -> 41.2 | M67: ='[7]ข้อมูลตัด ถ่านหิน'!D10 -> 42.3 | N67: =IFERROR(Condensate[[#This Row],[ยอดการใช้ Steam BHS]]*100/Condensate[[#This Row],[รวมยอดใช้สตีม]]/100,0) -> 0.49341317 | O67: =IFERROR(Condensate[[#This Row],[ยอดการใช้ Steam YUELI]]*100/Condensate[[#This Row],[รวมยอดใช้สตีม]]/100,0) -> 0.50658683 | P67: =SUM(Condensate[[#This Row],[ยอดการใช้ Steam BHS]:[ยอดการใช้ Steam YUELI]]) -> 83.5
A68: 45967 | B68: =VLOOKUP(Condensate[[#This Row],[วันที่]],'[6]TABLE DATA'!$V:$W,2,0) -> 17 | C68: =[7]มิเตอร์น้ำ!BD8 -> 85 | D68: =Condensate[[#This Row],[มิเตอร์น้ำ Boiler]]-Condensate[[#This Row],[Soft Mark Up]] -> 68 | E68: =E67 -> 0.8 | F68: =IFERROR(Condensate[[#This Row],[น้ำ CONDENSATE กลับ]]/Condensate[[#This Row],[รวมยอดใช้สตีม]],0) -> 0.79439252 | G68: =(Condensate[[#This Row],[% condensate ]]-Condensate[[#This Row],[Target]])/80*100 -> -0.0070093458 | H68: =IFERROR(Condensate[[#This Row],[ยอดการใช้ Steam BHS]]*Condensate[[#This Row],[น้ำ CONDENSATE กลับ]]/Condensate[[#This Row],[มิเตอร์น้ำ Boiler]],0) -> 23.28 | I68: =IFERROR(Condensate[[#This Row],[CON Return bhs]]/Condensate[[#This Row],[ยอดการใช้ Steam BHS]],0) -> 0.8 | J68: =IFERROR(Condensate[[#This Row],[ยอดการใช้ Steam YUELI]]*Condensate[[#This Row],[น้ำ CONDENSATE กลับ]]/Condensate[[#This Row],[มิเตอร์น้ำ Boiler]],0) -> 45.2 | K68: =IFERROR(Condensate[[#This Row],[CON Return yueli]]/Condensate[[#This Row],[ยอดการใช้ Steam YUELI]],0) -> 0.8 | L68: ='[7]ข้อมูลตัด ถ่านหิน'!C11 -> 29.1 | M68: ='[7]ข้อมูลตัด ถ่านหิน'!D11 -> 56.5 | N68: =IFERROR(Condensate[[#This Row],[ยอดการใช้ Steam BHS]]*100/Condensate[[#This Row],[รวมยอดใช้สตีม]]/100,0) -> 0.33995327 | O68: =IFERROR(Condensate[[#This Row],[ยอดการใช้ Steam YUELI]]*100/Condensate[[#This Row],[รวมยอดใช้สตีม]]/100,0) -> 0.66004673 | P68: =SUM(Condensate[[#This Row],[ยอดการใช้ Steam BHS]:[ยอดการใช้ Steam YUELI]]) -> 85.6
A69: 45968 | B69: =VLOOKUP(Condensate[[#This Row],[วันที่]],'[6]TABLE DATA'!$V:$W,2,0) -> 16 | C69: =[7]มิเตอร์น้ำ!BD9 -> 88 | D69: =Condensate[[#This Row],[มิเตอร์น้ำ Boiler]]-Condensate[[#This Row],[Soft Mark Up]] -> 72 | E69: =E68 -> 0.8 | F69: =IFERROR(Condensate[[#This Row],[น้ำ CONDENSATE กลับ]]/Condensate[[#This Row],[รวมยอดใช้สตีม]],0) -> 0.83623693 | G69: =(Condensate[[#This Row],[% condensate ]]-Condensate[[#This Row],[Target]])/80*100 -> 0.045296167 | H69: =IFERROR(Condensate[[#This Row],[ยอดการใช้ Steam BHS]]*Condensate[[#This Row],[น้ำ CONDENSATE กลับ]]/Condensate[[#This Row],[มิเตอร์น้ำ Boiler]],0) -> 31.336364 | I69: =IFERROR(Condensate[[#This Row],[CON Return bhs]]/Condensate[[#This Row],[ยอดการใช้ Steam BHS]],0) -> 0.81818182 | J69: =IFERROR(Condensate[[#This Row],[ยอดการใช้ Steam YUELI]]*Condensate[[#This Row],[น้ำ CONDENSATE กลับ]]/Condensate[[#This Row],[มิเตอร์น้ำ Boiler]],0) -> 39.109091 | K69: =IFERROR(Condensate[[#This Row],[CON Return yueli]]/Condensate[[#This Row],[ยอดการใช้ Steam YUELI]],0) -> 0.81818182 | L69: ='[7]ข้อมูลตัด ถ่านหิน'!C12 -> 38.3 | M69: ='[7]ข้อมูลตัด ถ่านหิน'!D12 -> 47.8 | N69: =IFERROR(Condensate[[#This Row],[ยอดการใช้ Steam BHS]]*100/Condensate[[#This Row],[รวมยอดใช้สตีม]]/100,0) -> 0.44483159 | O69: =IFERROR(Condensate[[#This Row],[ยอดการใช้ Steam YUELI]]*100/Condensate[[#This Row],[รวมยอดใช้สตีม]]/100,0) -> 0.55516841 | P69: =SUM(Condensate[[#This Row],[ยอดการใช้ Steam BHS]:[ยอดการใช้ Steam YUELI]]) -> 86.1
A70: 45969 | B70: =VLOOKUP(Condensate[[#This Row],[วันที่]],'[6]TABLE DATA'!$V:$W,2,0) -> 18 | C70: =[7]มิเตอร์น้ำ!BD10 -> 93 | D70: =Condensate[[#This Row],[มิเตอร์น้ำ Boiler]]-Condensate[[#This Row],[Soft Mark Up]] -> 75 | E70: =E69 -> 0.8 | F70: =IFERROR(Condensate[[#This Row],[น้ำ CONDENSATE กลับ]]/Condensate[[#This Row],[รวมยอดใช้สตีม]],0) -> 0.85714286 | G70: =(Condensate[[#This Row],[% condensate ]]-Condensate[[#This Row],[Target]])/80*100 -> 0.071428571 | H70: =IFERROR(Condensate[[#This Row],[ยอดการใช้ Steam BHS]]*Condensate[[#This Row],[น้ำ CONDENSATE กลับ]]/Condensate[[#This Row],[มิเตอร์น้ำ Boiler]],0) -> 32.822581 | I70: =IFERROR(Condensate[[#This Row],[CON Return bhs]]/Condensate[[#This Row],[ยอดการใช้ Steam BHS]],0) -> 0.80645161 | J70: =IFERROR(Condensate[[#This Row],[ยอดการใช้ Steam YUELI]]*Condensate[[#This Row],[น้ำ CONDENSATE กลับ]]/Condensate[[#This Row],[มิเตอร์น้ำ Boiler]],0) -> 37.741935 | K70: =IFERROR(Condensate[[#This Row],[CON Return yueli]]/Condensate[[#This Row],[ยอดการใช้ Steam YUELI]],0) -> 0.80645161 | L70: ='[7]ข้อมูลตัด ถ่านหิน'!C13 -> 40.7 | M70: ='[7]ข้อมูลตัด ถ่านหิน'!D13 -> 46.8 | N70: =IFERROR(Condensate[[#This Row],[ยอดการใช้ Steam BHS]]*100/Condensate[[#This Row],[รวมยอดใช้สตีม]]/100,0) -> 0.46514286 | O70: =IFERROR(Condensate[[#This Row],[ยอดการใช้ Steam YUELI]]*100/Condensate[[#This Row],[รวมยอดใช้สตีม]]/100,0) -> 0.53485714 | P70: =SUM(Condensate[[#This Row],[ยอดการใช้ Steam BHS]:[ยอดการใช้ Steam YUELI]]) -> 87.5
A71: 45970 | B71: =VLOOKUP(Condensate[[#This Row],[วันที่]],'[6]TABLE DATA'!$V:$W,2,0) -> 8 | C71: =[7]มิเตอร์น้ำ!BD11 -> 54 | D71: =Condensate[[#This Row],[มิเตอร์น้ำ Boiler]]-Condensate[[#This Row],[Soft Mark Up]] -> 46 | E71: =E70 -> 0.8 | F71: =IFERROR(Condensate[[#This Row],[น้ำ CONDENSATE กลับ]]/Condensate[[#This Row],[รวมยอดใช้สตีม]],0) -> 0.94845361 | G71: =(Condensate[[#This Row],[% condensate ]]-Condensate[[#This Row],[Target]])/80*100 -> 0.18556701 | H71: =IFERROR(Condensate[[#This Row],[ยอดการใช้ Steam BHS]]*Condensate[[#This Row],[น้ำ CONDENSATE กลับ]]/Condensate[[#This Row],[มิเตอร์น้ำ Boiler]],0) -> 18.144444 | I71: =IFERROR(Condensate[[#This Row],[CON Return bhs]]/Condensate[[#This Row],[ยอดการใช้ Steam BHS]],0) -> 0.85185185 | J71: =IFERROR(Condensate[[#This Row],[ยอดการใช้ Steam YUELI]]*Condensate[[#This Row],[น้ำ CONDENSATE กลับ]]/Condensate[[#This Row],[มิเตอร์น้ำ Boiler]],0) -> 23.17037 | K71: =IFERROR(Condensate[[#This Row],[CON Return yueli]]/Condensate[[#This Row],[ยอดการใช้ Steam YUELI]],0) -> 0.85185185 | L71: ='[7]ข้อมูลตัด ถ่านหิน'!C14 -> 21.3 | M71: ='[7]ข้อมูลตัด ถ่านหิน'!D14 -> 27.2 | N71: =IFERROR(Condensate[[#This Row],[ยอดการใช้ Steam BHS]]*100/Condensate[[#This Row],[รวมยอดใช้สตีม]]/100,0) -> 0.43917526 | O71: =IFERROR(Condensate[[#This Row],[ยอดการใช้ Steam YUELI]]*100/Condensate[[#This Row],[รวมยอดใช้สตีม]]/100,0) -> 0.56082474 | P71: =SUM(Condensate[[#This Row],[ยอดการใช้ Steam BHS]:[ยอดการใช้ Steam YUELI]]) -> 48.5
A72: 45971 | B72: =VLOOKUP(Condensate[[#This Row],[วันที่]],'[6]TABLE DATA'!$V:$W,2,0) -> 16 | C72: =[7]มิเตอร์น้ำ!BD12 -> 99 | D72: =Condensate[[#This Row],[มิเตอร์น้ำ Boiler]]-Condensate[[#This Row],[Soft Mark Up]] -> 83 | E72: =E71 -> 0.8 | F72: =IFERROR(Condensate[[#This Row],[น้ำ CONDENSATE กลับ]]/Condensate[[#This Row],[รวมยอดใช้สตีม]],0) -> 0.84607543 | G72: =(Condensate[[#This Row],[% condensate ]]-Condensate[[#This Row],[Target]])/80*100 -> 0.057594292 | H72: =IFERROR(Condensate[[#This Row],[ยอดการใช้ Steam BHS]]*Condensate[[#This Row],[น้ำ CONDENSATE กลับ]]/Condensate[[#This Row],[มิเตอร์น้ำ Boiler]],0) -> 34.709091 | I72: =IFERROR(Condensate[[#This Row],[CON Return bhs]]/Condensate[[#This Row],[ยอดการใช้ Steam BHS]],0) -> 0.83838384 | J72: =IFERROR(Condensate[[#This Row],[ยอดการใช้ Steam YUELI]]*Condensate[[#This Row],[น้ำ CONDENSATE กลับ]]/Condensate[[#This Row],[มิเตอร์น้ำ Boiler]],0) -> 47.536364 | K72: =IFERROR(Condensate[[#This Row],[CON Return yueli]]/Condensate[[#This Row],[ยอดการใช้ Steam YUELI]],0) -> 0.83838384 | L72: ='[7]ข้อมูลตัด ถ่านหิน'!C15 -> 41.4 | M72: ='[7]ข้อมูลตัด ถ่านหิน'!D15 -> 56.7 | N72: =IFERROR(Condensate[[#This Row],[ยอดการใช้ Steam BHS]]*100/Condensate[[#This Row],[รวมยอดใช้สตีม]]/100,0) -> 0.42201835 | O72: =IFERROR(Condensate[[#This Row],[ยอดการใช้ Steam YUELI]]*100/Condensate[[#This Row],[รวมยอดใช้สตีม]]/100,0) -> 0.57798165 | P72: =SUM(Condensate[[#This Row],[ยอดการใช้ Steam BHS]:[ยอดการใช้ Steam YUELI]]) -> 98.1
A73: 45972 | B73: =VLOOKUP(Condensate[[#This Row],[วันที่]],'[6]TABLE DATA'!$V:$W,2,0) -> 23 | C73: =[7]มิเตอร์น้ำ!BD13 -> 87 | D73: =Condensate[[#This Row],[มิเตอร์น้ำ Boiler]]-Condensate[[#This Row],[Soft Mark Up]] -> 64 | E73: =E72 -> 0.8 | F73: =IFERROR(Condensate[[#This Row],[น้ำ CONDENSATE กลับ]]/Condensate[[#This Row],[รวมยอดใช้สตีม]],0) -> 0.74853801 | G73: =(Condensate[[#This Row],[% condensate ]]-Condensate[[#This Row],[Target]])/80*100 -> -0.064327485 | H73: =IFERROR(Condensate[[#This Row],[ยอดการใช้ Steam BHS]]*Condensate[[#This Row],[น้ำ CONDENSATE กลับ]]/Condensate[[#This Row],[มิเตอร์น้ำ Boiler]],0) -> 30.308046 | I73: =IFERROR(Condensate[[#This Row],[CON Return bhs]]/Condensate[[#This Row],[ยอดการใช้ Steam BHS]],0) -> 0.73563218 | J73: =IFERROR(Condensate[[#This Row],[ยอดการใช้ Steam YUELI]]*Condensate[[#This Row],[น้ำ CONDENSATE กลับ]]/Condensate[[#This Row],[มิเตอร์น้ำ Boiler]],0) -> 32.588506 | K73: =IFERROR(Condensate[[#This Row],[CON Return yueli]]/Condensate[[#This Row],[ยอดการใช้ Steam YUELI]],0) -> 0.73563218 | L73: ='[7]ข้อมูลตัด ถ่านหิน'!C16 -> 41.2 | M73: ='[7]ข้อมูลตัด ถ่านหิน'!D16 -> 44.3 | N73: =IFERROR(Condensate[[#This Row],[ยอดการใช้ Steam BHS]]*100/Condensate[[#This Row],[รวมยอดใช้สตีม]]/100,0) -> 0.48187135 | O73: =IFERROR(Condensate[[#This Row],[ยอดการใช้ Steam YUELI]]*100/Condensate[[#This Row],[รวมยอดใช้สตีม]]/100,0) -> 0.51812865 | P73: =SUM(Condensate[[#This Row],[ยอดการใช้ Steam BHS]:[ยอดการใช้ Steam YUELI]]) -> 85.5
